Workbook

Sheet Test Scenarios
A1: Scenario ID | B1: Priority | C1: Module | D1: PRD Ref | E1: Test Scenario | F1: Why It Ranks Here | G1: No. of Test Cases
A2: TS-01 | B2: Critical | C2: Checkout | D2: FR-12 | E2: Verify checkout accepts only valid recipient, phone, address and payment details, and blocks invalid input | F2: Last step before money changes hands; bad validation means bad or undeliverable orders | G2: =COUNTIF('Test Cases'!$B:$B,A2) -> 15
A3: TS-02 | B3: Critical | C3: Order Confirmation | D3: FR-13 | E3: Verify placing an order creates a unique order number, shows correct confirmation and resets cart and coupon | F3: Proves the purchase actually completed and state is clean afterwards | G3: =COUNTIF('Test Cases'!$B:$B,A3) -> 6
A4: TS-03 | B4: Critical | C4: Order Total | D4: FR-08 | E4: Verify total = subtotal + delivery - discount everywhere it is shown | F4: Wrong money amounts directly hurt customers and the business | G4: =COUNTIF('Test Cases'!$B:$B,A4) -> 6
A5: TS-04 | B5: Critical | C5: Cart | D5: FR-05 | E5: Verify items can be added, edited and removed, and quantity rules and stock limits are enforced | F5: Core purchase path; stock and quantity errors cause oversell and wrong totals | G5: =COUNTIF('Test Cases'!$B:$B,A5) -> 14
A6: TS-05 | B6: High | C6: Coupons | D6: FR-06 | E6: Verify valid coupons apply the correct discount, invalid ones are rejected and discounts never stack | F6: Discount logic is a common source of revenue loss | G6: =COUNTIF('Test Cases'!$B:$B,A6) -> 10
A7: TS-06 | B7: High | C7: Delivery Fee | D7: FR-07 | E7: Verify the 2,000 delivery fee and the 500,000 free-delivery threshold, including the boundary | F7: Boundary rule with direct money impact | G7: =COUNTIF('Test Cases'!$B:$B,A7) -> 7
A8: TS-07 | B8: High | C8: Registration | D8: FR-09 | E8: Verify account creation rules for name, email, password and duplicate accounts | F8: Gate to checkout; weak validation lets bad data in | G8: =COUNTIF('Test Cases'!$B:$B,A8) -> 12
A9: TS-08 | B9: High | C9: Login | D9: FR-10 | E9: Verify valid login works and failures show one generic error | F9: Gate to checkout; also a security expectation | G9: =COUNTIF('Test Cases'!$B:$B,A9) -> 5
A10: TS-09 | B10: High | C10: Session | D10: FR-11 | E10: Verify login state, logout, and that guests are blocked from checkout | F10: Controls who can buy and see personal data | G10: =COUNTIF('Test Cases'!$B:$B,A10) -> 5
A11: TS-10 | B11: High | C11: Order History | D11: FR-14 | E11: Verify customers see only their own orders, newest first, with complete details | F11: Privacy (data separation) and customer trust | G11: =COUNTIF('Test Cases'!$B:$B,A11) -> 6
A12: TS-11 | B12: Medium | C12: Product Catalog | D12: FR-01 | E12: Verify catalog displays all products with correct details, price format and out-of-stock handling | F12: Entry point of the shopping journey | G12: =COUNTIF('Test Cases'!$B:$B,A12) -> 4
A13: TS-12 | B13: Medium | C13: Search | D13: FR-02 | E13: Verify search is case-insensitive, supports partial names and handles no results | F13: Main way customers find products | G13: =COUNTIF('Test Cases'!$B:$B,A13) -> 8
... A19: TS-18 | B19: Low | C19: Responsive Layout | D19: NFR (Sec. 5) | E19: Verify layout works down to small mobile widths without horizontal scroll | F19: Many customers shop on phones | G19: =COUNTIF('Test Cases'!$B:$B,A19) -> 3
F20: Total test cases | G20: =SUM(G2:G19) -> 117

Sheet Test Cases
A1: Test Case ID | B1: Scenario ID | C1: Module | D1: PRD Ref | E1: Priority | F1: Test Case Title | G1: Type | H1: Preconditions | I1: Test Steps | J1: Test Data | K1: Expected Result | L1: Actual Result | M1: Status | N1: Bug ID | O1: Tested By | P1: Date Tested | Q1: Remarks
A2: TC-001 | B2: TS-01 | C2: Checkout | D2: FR-12 | E2: Critical | F2: Place order with all valid details | G2: Positive | H2: App open in a fresh browser session (localStorage cleared). Test account already registered. | I2: 1. Log in with the test account 2. Add Tecno Spark 20 to the cart 3. Open Cart and click 'Go to checkout' 4. Enter valid recipient, phone, address 5. Select payment method Card 6. Click 'Place order' | J2: Test account: Test User / testuser1@example.com / Passw0rd123 | Recipient: Ade Bello | Phone: 08012345678 | Address: 12 Unity Road, Ilorin | Payment: Card | K2: Order is placed and the confirmation screen is shown with an order number. | L2: Order is placed and the confirmation screen is shown with an order number. | M2: Pass | O2: Olayemi | P2: 28/09/2026
A3: TC-002 | B3: TS-01 | C3: Checkout | D3: FR-12 | E3: Critical | F3: Submit with all checkout fields empty | G3: Negative | H3: App open in a fresh browser session (localStorage cleared). Logged in with items in cart. | I3: 1. Log in with the test account 2. Add Tecno Spark 20 to the cart 3. Open Cart and click 'Go to checkout' 4. Leave every field empty 5. Click 'Place order' | J3: All fields empty | K3: Order is not placed. A visible, specific error message is shown. | L3: Order is not placed. A visible, specific error message is shown. | M3: Pass | O3: Olayemi | P3: 28/09/2026
A4: TC-003 | B4: TS-01 | C4: Checkout | D4: FR-12 | E4: Critical | F4: Recipient name left empty | G4: Negative | H4: App open in a fresh browser session (localStorage cleared). Logged in with items in cart. | I4: 1. Log in with the test account 2. Add Tecno Spark 20 to the cart 3. Open Cart and click 'Go to checkout' 4. Leave Recipient name empty; fill other fields validly 5. Click 'Place order' | J4: Recipient: (empty) | Phone: 08012345678 | Address: 12 Unity Road, Ilorin | Payment: Card | K4: Order is not placed. Error tells the customer to enter the recipient name. | L4: Order is not placed. Error tells the customer to enter the recipient name. | M4: Pass | O4: Olayemi | P4: 28/09/2026
A5: TC-004 | B5: TS-01 | C5: Checkout | D5: FR-12 | E5: Critical | F5: Phone number left empty | G5: Negative | H5: App open in a fresh browser session (localStorage cleared). Logged in with items in cart. | I5: 1. Log in with the test account 2. Add Tecno Spark 20 to the cart 3. Open Cart and click 'Go to checkout' 4. Leave Phone empty; fill other fields validly 5. Click 'Place order' | J5: Phone: (empty) | K5: Order is not placed. Error tells the customer to enter a phone number. | L5: Order is not placed. Error tells the customer to enter a phone number. | M5: Pass | O5: Olayemi | P5: 28/09/2026
A6: TC-005 | B6: TS-01 | C6: Checkout | D6: FR-12 | E6: Critical | F6: Phone with 10 digits (one below required length) | G6: Boundary | H6: App open in a fresh browser session (localStorage cleared). Logged in with items in cart. | I6: 1. Log in with the test account 2. Add Tecno Spark 20 to the cart 3. Open Cart and click 'Go to checkout' 4. Enter a 10-digit phone number; fill other fields validly 5. Click 'Place order' | J6: Phone: 0801234567 | K6: Order is not placed. Error states the phone must be exactly 11 digits. | L6: Order is not placed. Error states the phone must be exactly 11 digits. | M6: Pass | O6: Olayemi | P6: 28/09/2026
A7: TC-006 | B7: TS-01 | C7: Checkout | D7: FR-12 | E7: Critical | F7: Phone with exactly 11 digits | G7: Boundary | H7: App open in a fresh browser session (localStorage cleared). Logged in with items in cart. | I7: 1. Log in with the test account 2. Add Tecno Spark 20 to the cart 3. Open Cart and click 'Go to checkout' 4. Enter an 11-digit phone number; fill other fields validly 5. Click 'Place order' | J7: Phone: 08012345678 | K7: Phone is accepted and the order is placed. | L7: Phone is accepted and the order is placed. | M7: Pass | O7: Olayemi | P7: 28/09/2026
A8: TC-007 | B8: TS-01 | C8: Checkout | D8: FR-12 | E8: Critical | F8: Phone with 12 digits (one above required length) | G8: Boundary | H8: App open in a fresh browser session (localStorage cleared). Logged in with items in cart. | I8: 1. Log in with the test account 2. Add Tecno Spark 20 to the cart 3. Open Cart and click 'Go to checkout' 4. Enter a 12-digit phone number; fill other fields validly 5. Click 'Place order' | J8: Phone: 080123456789 | K8: Order is not placed. Error states the phone must be exactly 11 digits. | L8: Order is placed,more than 11 didgit phone number is accepted no error is stated | M8: Fail | N8: BUG-001 | O8: Olayemi | P8: 28/09/2026
A9: TC-008 | B9: TS-01 | C9: Checkout | D9: FR-12 | E9: Critical | F9: Phone containing letters (11 characters) | G9: Negative | H9: App open in a fresh browser session (localStorage cleared). Logged in with items in cart. | I9: 1. Log in with the test account 2. Add Tecno Spark 20 to the cart 3. Open Cart and click 'Go to checkout' 4. Enter an 11-character phone containing letters; fill other fields validly 5. Click 'Place order' | J9: Phone: 0801234abcd | K9: Order is not placed. Letters are rejected; error says digits only. | L9: Order is placed, letters are accepted,no error is stated | M9: Fail | N9: BUG-002 | O9: Olayemi | P9: 28/09/2026
A10: TC-009 | B10: TS-01 | C10: Checkout | D10: FR-12 | E10: Critical | F10: Phone containing symbols (11 characters) | G10: Negative | H10: App open in a fresh browser session (localStorage cleared). Logged in with items in cart. | I10: 1. Log in with the test account 2. Add Tecno Spark 20 to the cart 3. Open Cart and click 'Go to checkout' 4. Enter an 11-character phone containing a + and symbols; fill other fields validly 5. Click 'Place order' | J10: Phone: +2348012345 | K10: Order is not placed. Symbols are rejected; error says digits only. | L10: Order is placed, symbols are accepted , no error is stated | M10: Fail | N10: BUG-003 | O10: Olayemi | P10: 28/09/2026
A11: TC-010 | B11: TS-01 | C11: Checkout | D11: FR-12 | E11: Critical | F11: Delivery address left empty | G11: Negative | H11: App open in a fresh browser session (localStorage cleared). Logged in with items in cart. | I11: 1. Log in with the test account 2. Add Tecno Spark 20 to the cart 3. Open Cart and click 'Go to checkout' 4. Leave Address empty; fill other fields validly 5. Click 'Place order' | J11: Address: (empty) | K11: Order is not placed. Error tells the customer to enter a delivery address. | L11: Order is not placed. Error tells the customer to enter a delivery address. | M11: Pass | O11: Olayemi | P11: 28/09/2026
A12: TC-011 | B12: TS-01 | C12: Checkout | D12: FR-12 | E12: Critical | F12: Delivery address with spaces only | G12: Negative | H12: App open in a fresh browser session (localStorage cleared). Logged in with items in cart. | I12: 1. Log in with the test account 2. Add Tecno Spark 20 to the cart 3. Open Cart and click 'Go to checkout' 4. Enter only spaces in Address; fill other fields validly 5. Click 'Place order' | J12: Address: 5 spaces | K12: Order is not placed. Whitespace-only address is rejected. | L12: Order is not placed. Whitespace-only address is rejected. | M12: Pass | O12: Olayemi | P12: 28/09/2026
A13: TC-012 | B13: TS-01 | C13: Checkout | D13: FR-12 | E13: Critical | F13: Delivery address below the minimum length | G13: Negative | H13: App open in a fresh browser session (localStorage cleared). Logged in with items in cart. | I13: 1. Log in with the test account 2. Add Tecno Spark 20 to the cart 3. Open Cart and click 'Go to checkout' 4. Enter a very short address; fill other fields validly 5. Click 'Place order' | J13: Address: abc | K13: Order is not placed. Error asks for a full delivery address. | L13: Order is not placed. Error asks for a full delivery address. | M13: Pass | O13: Olayemi | P13: 29/09/2026
A14: TC-013 | B14: TS-01 | C14: Checkout | D14: FR-12 | E14: Critical | F14: No payment method selected | G14: Negative | H14: App open in a fresh browser session (localStorage cleared). Logged in with items in cart. | I14: 1. Log in with the test account 2. Add Tecno Spark 20 to the cart 3. Open Cart and click 'Go to checkout' 4. Fill all fields validly 5. Leave Payment method on 'Select' 6. Click 'Place order' | J14: Payment: (not selected) | K14: Order is not placed. Error tells the customer to select a payment method. | L14: Order is not placed. Error tells the customer to select a payment method. | M14: Pass | O14: Olayemi | P14: 29/09/2026
A15: TC-014 | B15: TS-01 | C15: Checkout | D15: FR-12 | E15: Critical | F15: Order can be placed with each payment method | G15: Positive | H15: App open in a fresh browser session (localStorage cleared). Logged in. | I15: 1. Log in with the test account 2. Add an item, go to checkout, fill valid details, choose Card, place order 3. Repeat with Bank transfer 4. Repeat with Pay on delivery | J15: Recipient: Ade Bello | Phone: 08012345678 | Address: 12 Unity Road, Ilorin | Payment: each of: Card, Bank transfer, Pay on delivery | K15: All three methods result in a placed order. Order history shows the chosen method for each. | L15: All three methods result in a placed order. Order history shows the chosen method for each. | M15: Pass | O15: Olayemi | P15: 29/09/2026
A16: TC-015 | B16: TS-01 | C16: Checkout | D16: FR-12 | E16: Critical | F16: Total at checkout equals cart total | G16: Positive | H16: App open in a fresh browser session (localStorage cleared). Logged in. | I16: 1. Log in with the test account 2. Add Tecno Spark 20 x1 and Anker 20W Charger x2 3. Note the cart Total 4. Click 'Go to checkout' and note the amount to pay | J16: Items: Tecno Spark 20 x1, Anker 20W Charger x2 | K16: Amount to pay at checkout equals the cart Total exactly. | L16: Amount to pay at checkout equals the cart Total exactly. | M16: Pass | O16: Olayemi | P16: 29/09/2026
A17: TC-016 | B17: TS-02 | C17: Order Confirmation | D17: FR-13 | E17: Critical | F17: Confirmation shows order number and total paid | G17: Positive | H17: App open in a fresh browser session (localStorage cleared). Logged in with items in cart. | I17: 1. Log in with the test account 2. Add Tecno Spark 20 to the cart 3. Open Cart and click 'Go to checkout' 4. Enter valid details and place the order | J17: Recipient: Ade Bello | Phone: 08012345678 | Address: 12 Unity Road, Ilorin | Payment: Card | K17: Confirmation shows a generated order number and the total paid. | L17: Confirmation shows a generated order number and the total paid. | M17: Pass | O17: Olayemi | P17: 29/09/2026
A18: TC-017 | B18: TS-02 | C18: Order Confirmation | D18: FR-13 | E18: Critical | F18: Cart is cleared after placing an order | G18: Positive | H18: App open in a fresh browser session (localStorage cleared). Logged in with items in cart. | I18: 1. Log in with the test account 2. Add Tecno Spark 20 to the cart 3. Open Cart and click 'Go to checkout' 4. Enter valid details and place the order 5. Check the cart count in the header 6. Open Cart | J18: Recipient: Ade Bello | Phone: 08012345678 | Address: 12 Unity Road, Ilorin | Payment: Card | K18: Cart count shows 0 and the Cart page shows the empty-cart message. | L18: Cart count shows 0 and the Cart page shows the empty-cart message. | M18: Pass | O18: Olayemi | P18: 29/09/2026
A19: TC-018 | B19: TS-02 | C19: Order Confirmation | D19: FR-13 | E19: Critical | F19: Applied coupon is cleared after placing an order | G19: Positive | H19: App open in a fresh browser session (localStorage cleared). Logged in. | I19: 1. Log in with the test account 2. Add Tecno Spark 20, apply coupon SAVE10 in Cart 3. Go to checkout and place an order with valid details 4. Add Tecno Spark 20 to the cart again and open Cart | J19: Coupon: SAVE10 | Recipient: Ade Bello | Phone: 08012345678 | Address: 12 Unity Road, Ilorin | Payment: Card | K19: The new cart shows no coupon applied and no discount. | L19: The new cart shows no coupon applied and no discount. | M19: Pass | O19: Olayemi | P19: 29/09/2026
A20: TC-019 | B20: TS-02 | C20: Order Confirmation | D20: FR-13 | E20: Critical | F20: Order numbers are unique across orders | G20: Positive | H20: App open in a fresh browser session (localStorage cleared). Logged in. | I20: 1. Log in with the test account 2. Place one order and note the order number 3. Place a second order and note the order number | J20: Recipient: Ade Bello | Phone: 08012345678 | Address: 12 Unity Road, Ilorin | Payment: Card | K20: The two order numbers are different. | L20: The two order numbers are different. | M20: Pass | O20: Olayemi | P20: 29/09/2026
A21: TC-020 | B21: TS-02 | C21: Order Confirmation | D21: FR-13 | E21: Critical | F21: Total paid on confirmation matches checkout total | G21: Positive | H21: App open in a fresh browser session (localStorage cleared). Logged in. | I21: 1. Log in with the test account 2. Add Tecno Spark 20 x1, go to checkout and note the amount to pay 3. Place the order and read the total on the confirmation screen | J21: Recipient: Ade Bello | Phone: 08012345678 | Address: 12 Unity Road, Ilorin | Payment: Card | K21: Total paid on confirmation equals the amount shown at checkout. | L21: Total paid on confirmation equals the amount shown at checkout. | M21: Pass | O21: Olayemi | P21: 29/09/2026
A22: TC-021 | B22: TS-02 | C22: Order Confirmation | D22: FR-13 | E22: Critical | F22: Double-click 'Place order' | G22: Negative | H22: App open in a fresh browser session (localStorage cleared). Logged in with items in cart. | I22: 1. Log in with the test account 2. Add Tecno Spark 20 to the cart 3. Open Cart and click 'Go to checkout' 4. Fill valid details 5. Double-click 'Place order' quickly 6. Open Orders | J22: Recipient: Ade Bello | Phone: 08012345678 | Address: 12 Unity Road, Ilorin | Payment: Card | K22: Only one order is created for the cart. | L22: Only one order is created for the cart. | M22: Pass | O22: Olayemi | P22: 29/09/2026 | Q22: Implied by FR-13 (unique order number, cart cleared). Confirm intent if the result is unclear.
A23: TC-022 | B23: TS-03 | C23: Order Total | D23: FR-08 | E23: Critical | F23: Total for a single item below the free-delivery threshold | G23: Positive | H23: App open in a fresh browser session (localStorage cleared). | I23: 1. Add Tecno Spark 20 x1 to the cart 2. Open Cart and read Subtotal, Delivery, Discount, Total | J23: Tecno Spark 20 = 145,000 | K23: Subtotal 145,000 | Delivery 2,000 | Discount 0 | Total 147,000. | L23: Subtotal 145,000 | Delivery 2,000 | Discount 0 | Total 147,000. | M23: Pass | O23: Olayemi | P23: 29/09/2026
A24: TC-023 | B24: TS-03 | C24: Order Total | D24: FR-08 | E24: Critical | F24: Total for multiple items | G24: Positive | H24: App open in a fresh browser session (localStorage cleared). | I24: 1. Add Tecno Spark 20 x1 2. Add Anker 20W Charger x2 3. Open Cart and read the totals | J24: 145,000 + (2 x 12,500) | K24: Subtotal 170,000 | Delivery 2,000 | Total 172,000. | L24: Subtotal 170,000 | Delivery 2,000 | Total 172,000. | M24: Pass | O24: Olayemi | P24: 29/09/2026
A25: TC-024 | B25: TS-03 | C25: Order Total | D25: FR-08 | E25: Critical | F25: Total with a coupon applied | G25: Positive | H25: App open in a fresh browser session (localStorage cleared). | I25: 1. Add Tecno Spark 20 x1 and Anker 20W Charger x2 2. Open Cart and apply coupon SAVE10 3. Read the totals | J25: Subtotal 170,000 | Coupon SAVE10 | K25: Discount 17,000 | Delivery 2,000 | Total 155,000. | L25: Discount 17,000 | Delivery 2,000 | Total 155,000. | M25: Pass | O25: Olayemi | P25: 29/09/2026
A26: TC-025 | B26: TS-03 | C26: Order Total | D26: FR-08 | E26: Critical | F26: Total updates when quantity changes | G26: Positive | H26: App open in a fresh browser session (localStorage cleared). | I26: 1. Add Tecno Spark 20 x1 2. Open Cart and change quantity to 3 3. Read the totals | J26: Quantity 1 to 3 | K26: Subtotal 435,000 | Delivery 2,000 | Total 437,000. | L26: Subtotal 435,000 | Delivery 2,000 | Total 437,000. | M26: Pass | O26: Olayemi | P26: 29/09/2026
A27: TC-026 | B27: TS-03 | C27: Order Total | D27: FR-08 | E27: Critical | F27: Total updates when an item is removed | G27: Positive | H27: App open in a fresh browser session (localStorage cleared). | I27: 1. Add Tecno Spark 20 x1 and Anker 20W Charger x2 2. Open Cart and remove the Anker charger 3. Read the totals | J27: Remove Anker 20W Charger | K27: Subtotal 145,000 | Delivery 2,000 | Total 147,000. | L27: Subtotal 145,000 | Delivery 2,000 | Total 147,000. | M27: Pass | O27: Olayemi | P27: 29/09/2026
A28: TC-027 | B28: TS-03 | C28: Order Total | D28: FR-08 | E28: Critical | F28: Total is identical in cart, checkout and confirmation | G28: Positive | H28: App open in a fresh browser session (localStorage cleared). Logged in. | I28: 1. Log in with the test account 2. Add Tecno Spark 20 x1 and Anker 20W Charger x2 and apply SAVE10 3. Compare Total in Cart, amount at checkout, and Total paid on confirmation | J28: Recipient: Ade Bello | Phone: 08012345678 | Address: 12 Unity Road, Ilorin | Payment: Card | K28: All three screens show the same amount. | L28: All three screens show the same amount. | M28: Pass | O28: Olayemi | P28: 29/09/2026
A29: TC-028 | B29: TS-04 | C29: Cart | D29: FR-05 | E29: Critical | F29: Add an in-stock product to the cart | G29: Positive | H29: App open in a fresh browser session (localStorage cleared). | I29: 1. Click 'Add to cart' on Tecno Spark 20 | J29: Tecno Spark 20 | K29: Product is added; header cart count is 1; a line appears in Cart. | L29: Product is added; header cart count is 1; a line appears in Cart. | M29: Pass | O29: Olayemi | P29: 29/09/2026
A30: TC-029 | B30: TS-04 | C30: Cart | D30: FR-05 | E30: Critical | F30: Add the same product twice increments quantity | G30: Positive | H30: App open in a fresh browser session (localStorage cleared). | I30: 1. Click 'Add to cart' on Tecno Spark 20 twice 2. Open Cart | J30: Tecno Spark 20 | K30: One cart line with quantity 2 (not two separate lines). | L30: One cart line with quantity 2 (not two separate lines). | M30: Pass | O30: Olayemi | P30: 29/09/2026
A31: TC-030 | B31: TS-04 | C31: Cart | D31: FR-05 | E31: Critical | F31: Add different products | G31: Positive | H31: App open in a fresh browser session (localStorage cleared). | I31: 1. Add Tecno Spark 20 2. Add JBL Flip 6 Speaker 3. Open Cart | J31: Two different products | K31: Two separate lines; header count is 2. | L31: Two separate lines; header count is 2. | M31: Pass | O31: Olayemi | P31: 29/09/2026
A32: TC-031 | B32: TS-04 | C32: Cart | D32: FR-05 | E32: Critical | F32: Quantity equal to available stock | G32: Boundary | H32: App open in a fresh browser session (localStorage cleared). | I32: 1. Add JBL Flip 6 Speaker to the cart 2. Open Cart and set quantity to 7 | J32: JBL Flip 6 stock: 7 | Quantity: 7 | K32: Quantity 7 is accepted. | L32: Quantity 7 is accepted. | M32: Pass | O32: Olayemi | P32: 29/09/2026
A33: TC-032 | B33: TS-04 | C33: Cart | D33: FR-05 | E33: Critical | F33: Quantity one above available stock | G33: Boundary | H33: App open in a fresh browser session (localStorage cleared). | I33: 1. Add JBL Flip 6 Speaker to the cart 2. Open Cart and set quantity to 8 | J33: JBL Flip 6 stock: 7 | Quantity: 8 | K33: Quantity 8 is rejected or capped at stock; a message explains why. | L33: Quantity 8 is accepted,no error message | M33: Fail | N33: BUG-004 | O33: Olayemi | P33: 29/09/2026
A34: TC-033 | B34: TS-04 | C34: Cart | D34: FR-05 | E34: Critical | F34: Add to cart repeatedly beyond available stock | G34: Negative | H34: App open in a fresh browser session (localStorage cleared). | I34: 1. Click 'Add to cart' on Lenovo ThinkPad E14 three times 2. Open Cart | J34: ThinkPad E14 stock: 2 | K34: Cart never holds more than 2; the third add is blocked with a clear message. | L34: Cart holds more than 2; the third add is not blocked and no clear message. | M34: Fail | N34: BUG-005 | O34: Olayemi | P34: 29/09/2026
A35: TC-034 | B35: TS-04 | C35: Cart | D35: FR-05 | E35: Critical | F35: Quantity set to 0 | G35: Negative | H35: App open in a fresh browser session (localStorage cleared). | I35: 1. Add Tecno Spark 20 2. Open Cart and set quantity to 0 | J35: Quantity: 0 | K35: Value is rejected. Quantity stays at 1 or more. | L35: 0 Value is not rejected. | M35: Fail | N35: BUG-006 | O35: Olayemi | P35: 29/09/2026
A36: TC-035 | B36: TS-04 | C36: Cart | D36: FR-05 | E36: Critical | F36: Quantity set to a negative number | G36: Negative | H36: App open in a fresh browser session (localStorage cleared). | I36: 1. Add Tecno Spark 20 2. Open Cart and set quantity to -1 | J36: Quantity: -1 | K36: Value is rejected. Line total and Subtotal are never negative. | L36: negative Value is accepted. Line total and Subtotal are negative. | M36: Fail | N36: BUG-007 | O36: Olayemi | P36: 29/09/2026
A37: TC-036 | B37: TS-04 | C37: Cart | D37: FR-05 | E37: Critical | F37: Quantity set to a decimal | G37: Negative | H37: App open in a fresh browser session (localStorage cleared). | I37: 1. Add Tecno Spark 20 2. Open Cart and set quantity to 1.5 | J37: Quantity: 1.5 | K37: Value is rejected; only whole numbers are accepted. | L37: Value is rejected; only whole numbers are accepted. | M37: Pass | O37: Olayemi | P37: 29/09/2026
A38: TC-037 | B38: TS-04 | C38: Cart | D38: FR-05 | E38: Critical | F38: Quantity field cleared or non-numeric | G38: Negative | H38: App open in a fresh browser session (localStorage cleared). | I38: 1. Add Tecno Spark 20 2. Open Cart, clear the quantity field, then try typing letters | J38: Quantity: (empty) / abc | K38: Value is rejected; quantity stays a whole number of 1 or more. | L38: Value is blocked/rejected; quantity stays a whole number of 1 or more. | M38: Pass | O38: Olayemi | P38: 29/09/2026
A39: TC-038 | B39: TS-04 | C39: Cart | D39: FR-05 | E39: Critical | F39: Editing quantity updates the line total | G39: Positive | H39: App open in a fresh browser session (localStorage cleared). | I39: 1. Add Anker 20W Charger 2. Open Cart and set quantity to 4 | J39: 12,500 x 4 | K39: Line total shows 50,000. | L39: Line total shows 50,000. | M39: Pass | O39: Olayemi | P39: 29/09/2026
A40: TC-039 | B40: TS-04 | C40: Cart | D40: FR-05 | E40: Critical | F40: Remove an item from the cart | G40: Positive | H40: App open in a fresh browser session (localStorage cleared). | I40: 1. Add Tecno Spark 20 and JBL Flip 6 Speaker 2. Open Cart and click Remove on Tecno Spark 20 | J40: Remove Tecno Spark 20 | K40: Only that line is deleted; the other line and the count remain correct. | L40: Only that line is deleted; the other line and the count remain correct. | M40: Pass | O40: Olayemi | P40: 29/09/2026
...

Sheet Bug Report
A1: Bug ID | B1: Bug Title | C1: Module | D1: PRD Ref | E1: Related Test Case ID | F1: Severity | G1: Priority | H1: Status | I1: Environment (Browser / OS / Version) | J1: Preconditions | K1: Steps to Reproduce | L1: Expected Result | M1: Actual Result | N1: Evidence (Screenshot / Video Link) | O1: Reported By | P1: Date Reported | Q1: Assigned To | R1: Retest Result | S1: Date Closed | T1: Remarks
A2: BUG-001 | B2: Checkout accepts phone numbers longer than 11 digits with no validation error | C2: Checkout | D2: FR-12 | E2: TC-008 | F2: Major | G2: High | H2: New | I2: Google Chrome Browser | J2: Logged in with items in cart | K2: Go to checkout > enter a phone number of 12 digits (e.g. 080123456789) > fill other fields validly > click "Place order | L2: Order is not placed. Error states the phone must be exactly 11 digits. | M2: A phone number longer than 11 digits is accepted with no error shown. | P2: 28/09/2026
A3: BUG-002 | B3: Checkout accepts letters in the phone number field | C3: Checkout | D3: FR-12 | E3: TC-009 | F3: Major | G3: High | H3: New | I3: Google Chrome Browser | J3: Logged in with items in cart | K3: Go to checkout > enter phone number 0801234abcd (11 characters, contains letters) > fill other fields validly > click "Place order" | L3: Order is not placed. Letters are rejected; error says digits only. | M3: Order is placed. Letters are accepted in the phone field with no error shown. | P3: 28/09/2026
A4: BUG-003 | B4: Checkout accepts symbols and more than 11 characters in the phone number | C4: Checkout | D4: FR-12 | E4: TC-010 | F4: Major | G4: High | H4: New | I4: Google Chrome Browser | J4: Logged in with items in cart | K4: Go to checkout > enter phone number +2348012345 (contains a symbol, 11 characters) > fill other fields validly > click "Place order" | L4: Symbols are rejected; error says digits only. | M4: Order is placed. Symbols are accepted, with no error shown. | P4: 28/09/2026
A5: BUG-004
A6: BUG-005
A7: BUG-006
A8: BUG-007
A9: BUG-008
A10: BUG-009
A11: BUG-010
A12: BUG-011
A13: BUG-012
A14: BUG-013
A15: BUG-014
A16: BUG-015
... A61: BUG-060

Sheet Read Me & Summary
A1: Voltcart Test Documentation
A2: Product | B2: Voltcart gadget store. Source of truth: Voltcart PRD v1.0 (FR-01 to FR-14 plus non-functional expectations).
A3: Tabs | B3: Test Scenarios (ranked by importance) > Test Cases (linked by Scenario ID) > Bug Report (blank log).
A5: Execution summary (updates live)
A6: Total test cases | B6: =COUNTA('Test Cases'!A2:A118) -> 117
A7: Not Run | B7: =COUNTIF('Test Cases'!M2:M118,"Not Run") -> 0
A8: Pass | B8: =COUNTIF('Test Cases'!M2:M118,"Pass") -> 97
A9: Fail | B9: =COUNTIF('Test Cases'!M2:M118,"Fail") -> 20
A10: Blocked | B10: =COUNTIF('Test Cases'!M2:M118,"Blocked") -> 0
A11: Skipped | B11: =COUNTIF('Test Cases'!M2:M118,"Skipped") -> 0
A12: Pass rate (of executed cases) | B12: =IFERROR(B8/(B8+B9+B10),"No cases executed yet") -> 0.82905983
A13: Bugs logged | B13: =COUNTA('Bug Report'!B2:B61) -> 3
A14: Bugs still open | B14: =COUNTIFS('Bug Report'!B2:B61,"<>",'Bug Report'!H2:H61,"<>Closed",'Bug Report'!H2:H61,"<>Rejected") -> 3
A23: Severity (impact on the product)
A24: Critical | B24: Blocks a core journey or causes wrong money amounts or data loss (e.g. cannot place order, wrong total).
A25: Major | B25: Important feature works incorrectly but a workaround exists.
A26: Minor | B26: Small functional or validation issue with low business impact.
A27: Trivial | B27: Cosmetic issue (spelling, alignment, styling).
A29: Priority (urgency to fix)
A30: High | B30: Fix immediately, before release.
A31: Medium | B31: Fix in the current cycle.
A32: Low | B32: Fix when time allows.
A37: Environment tip | B37: Always record browser name and version, OS, and screen size in the Bug Report Environment column.
